Workbook

Sheet Dashboard
A1: UPRVUNL — Coal Rake Diversion Solver Dashboard
A3: Variable Cost (VC) optimisation across TPS through inter-plant rake diversion, subject to source-wise and plant-wise boundary conditions | July 2026
A5: Total Rakes (Conserved) | C5: Weighted Avg VC — Current | E5: Weighted Avg VC — After Diversion | G5: Max Plant VC — After Diversion | J5: Target VC (Ceiling) | L5: Active Diversion Moves
A6: ='July 2026 (3)'!F30 -> 390 | C6: =(SUMPRODUCT('July 2026 (3)'!D9,'July 2026 (3)'!E9)+SUMPRODUCT('July 2026 (3)'!D14,'July 2026 (3)'!E14)+SUMPRODUCT('July 2026 (3)'!D18,'July 2026 (3)'!E18)+SUMPRODUCT('July 2026 (3)'!D23,'July 2026 (3)'!E23)+SUMPRODUCT('July 2026 (3)'!D29,'July 2026 (3)'!E29))/'July 2026 (3)'!D30 -> 4.0225641 | E6: ='July 2026 (3)'!I15 -> 3.9637569 | G6: ='July 2026 (3)'!I9 -> 4.1305987 | J6: ='July 2026 (3)'!O17 -> 3.99 | L6: ='July 2026 (3)'!O22 -> 18
A9: Plant-wise Variable Cost — Current vs. Post-Diversion
A10: Thermal Power Station | B10: Rakes — Current | C10: Rakes — Diverted | D10: Δ Rakes | E10: VC — Current (Rs/Unit) | F10: VC — Diverted (Rs/Unit) | G10: Δ VC (Rs/Unit) | H10: Target VC | I10: Status
A11: Harduaganj (2X250 MW) | B11: ='July 2026 (3)'!D9 -> 60 | C11: ='July 2026 (3)'!F9 -> 65.044527 | D11: =C11-B11 -> 5.0445275 | E11: ='July 2026 (3)'!E9 -> 4.1933333 | F11: ='July 2026 (3)'!G9 -> 4.1305987 | G11: =F11-E11 -> -0.062734623 | H11: ='July 2026 (3)'!$O$17 -> 3.99 | I11: =IF(F11<=H11,"Within Target","Above Target") -> Above Target
A12: Harduaganj (1X660 MW) | B12: ='July 2026 (3)'!D14 -> 65 | C12: ='July 2026 (3)'!F14 -> 71.500001 | D12: =C12-B12 -> 6.500001 | E12: ='July 2026 (3)'!E14 -> 4.02 | F12: ='July 2026 (3)'!G14 -> 3.9900001 | G12: =F12-E12 -> -0.02999993 | H12: ='July 2026 (3)'!$O$17 -> 3.99 | I12: =IF(F12<=H12,"Within Target","Above Target") -> Above Target
A13: Parichha | B13: ='July 2026 (3)'!D18 -> 85 | C13: ='July 2026 (3)'!F18 -> 68 | D13: =C13-B13 -> -17 | E13: ='July 2026 (3)'!E18 -> 3.83 | F13: ='July 2026 (3)'!G18 -> 3.99 | G13: =F13-E13 -> 0.16 | H13: ='July 2026 (3)'!$O$17 -> 3.99 | I13: =IF(F13<=H13,"Within Target","Above Target") -> Within Target
A14: Panki | B14: ='July 2026 (3)'!D23 -> 60 | C14: ='July 2026 (3)'!F23 -> 66 | D14: =C14-B14 -> 6 | E14: ='July 2026 (3)'!E23 -> 3.31 | F14: ='July 2026 (3)'!G23 -> 3.6963636 | G14: =F14-E14 -> 0.38636364 | H14: ='July 2026 (3)'!$O$17 -> 3.99 | I14: =IF(F14<=H14,"Within Target","Above Target") -> Within Target
A15: Jawaharpur* | B15: ='July 2026 (3)'!D29 -> 120 | C15: ='July 2026 (3)'!F29 -> 119.45547 | D15: =C15-B15 -> -0.54452847 | E15: ='July 2026 (3)'!E29 -> 4.43125 | F15: ='July 2026 (3)'!G29 -> 3.99 | G15: =F15-E15 -> -0.44125004 | H15: ='July 2026 (3)'!$O$17 -> 3.99 | I15: =IF(F15<=H15,"Within Target","Above Target") -> Within Target
A16: Total / Weighted Average | B16: =SUM(B11:B15) -> 390 | C16: =SUM(C11:C15) -> 390 | D16: =C16-B16 -> 0 | E16: =SUMPRODUCT(B11:B15,E11:E15)/B16 -> 4.0225641 | F16: =SUMPRODUCT(C11:C15,F11:F15)/C16 -> 3.9637569 | G16: =F16-E16 -> -0.05880724
A18: Inter-Plant Rake Diversion Matrix — Δ Rakes by Coal Source (Diverted − Current)
A19: Coal Company | B19: Harduaganj (2X250 MW) | C19: Harduaganj (1X660 MW) | D19: Parichha | E19: Panki | F19: Jawaharpur* | G19: Company Total (Current) | H19: Company Total (Diverted) | I19: Conserved?
A20: NCL | B20: – | C20: ='July 2026 (3)'!F12-'July 2026 (3)'!D12 -> -1e-06 | D20: ='July 2026 (3)'!F15-'July 2026 (3)'!D15 -> -35.471698 | E20: ='July 2026 (3)'!F22-'July 2026 (3)'!D22 -> 0 | F20: ='July 2026 (3)'!F27-'July 2026 (3)'!D27 -> 35.471699 | G20: ='July 2026 (3)'!D31 -> 60 | H20: ='July 2026 (3)'!F31 -> 60 | I20: =IF(G20=H20,"Yes","No") -> Yes
A21: BCCL | B21: ='July 2026 (3)'!F7-'July 2026 (3)'!D7 -> -2.9554725 | C21: ='July 2026 (3)'!F13-'July 2026 (3)'!D13 -> -0.42566967 | D21: ='July 2026 (3)'!F17-'July 2026 (3)'!D17 -> 13.471698 | E21: ='July 2026 (3)'!F20-'July 2026 (3)'!D20 -> 25 | F21: ='July 2026 (3)'!F25-'July 2026 (3)'!D25 -> -35.090556 | G21: ='July 2026 (3)'!D32 -> 110 | H21: ='July 2026 (3)'!F32 -> 110 | I21: =IF(G21=H21,"Yes","No") -> Yes
A22: CCL | B22: ='July 2026 (3)'!F8-'July 2026 (3)'!D8 -> 8 | C22: ='July 2026 (3)'!F10-'July 2026 (3)'!D10 -> 6 | D22: ='July 2026 (3)'!F16-'July 2026 (3)'!D16 -> 5 | E22: ='July 2026 (3)'!F19-'July 2026 (3)'!D19 -> -19 | F22: ='July 2026 (3)'!F24-'July 2026 (3)'!D24 -> -7.1054274e-15 | G22: ='July 2026 (3)'!D33 -> 155 | H22: ='July 2026 (3)'!F33 -> 155 | I22: =IF(G22=H22,"Yes","No") -> Yes
A23: SECL | B23: – | C23: ='July 2026 (3)'!F11-'July 2026 (3)'!D11 -> 0.92567167 | D23: – | E23: ='July 2026 (3)'!F21-'July 2026 (3)'!D21 -> 0 | F23: ='July 2026 (3)'!F26-'July 2026 (3)'!D26 -> -0.92567167 | G23: ='July 2026 (3)'!D34 -> 65 | H23: ='July 2026 (3)'!F34 -> 65 | I23: =IF(G23=H23,"Yes","No") -> Yes
A24: ECL | B24: – | C24: – | D24: – | E24: – | F24: ='July 2026 (3)'!F28-'July 2026 (3)'!D28 -> 0 | G24: ='July 2026 (3)'!D35 -> 0 | H24: ='July 2026 (3)'!F35 -> 0 | I24: =IF(G24=H24,"Yes","No") -> Yes
A25: Note: Green = rakes gained by that TPS from the source; Red = rakes given up. Each coal company's grand total (columns G–H) is held constant by the Solver's conservation constraint.
A26: Solver Boundary Conditions & Constraint Check
A27: Constraint | B27: Lower Bound | C27: Upper Bound | D27: Basis | E27: Status
A28: Individual coal source (per plant) | B28: ='July 2026 (3)'!O7 -> 0.4 | C28: ='July 2026 (3)'!P7 -> 1.2 | D28: % of current rakes for that source at that plant
A29: Plant-wise total rakes | B29: ='July 2026 (3)'!O8 -> 0.8 | C29: ='July 2026 (3)'!P8 -> 1.1 | D29: % of current total rakes at that plant
A30: Target VC ceiling (aspirational) | B30: – | C30: ='July 2026 (3)'!O17 -> 3.99 | D30: Rs/Unit — applies to each TPS's post-diversion VC
A32: Total rakes conserved (Σ Diverted = Σ Current) | B32: ='July 2026 (3)'!D30 -> 390 | C32: ='July 2026 (3)'!F30 -> 390 | D32: Current total vs. Diverted total | E32: =IF(B32=C32,"Conserved","MISMATCH") -> Conserved
A33: Active diversion moves (non-zero Δ rakes) | B33: ='July 2026 (3)'!O22 -> 18 | D33: Count of coal-source × plant cells with a diversion program value
A35: How to re-run: open the source sheet, Data → Solver — objective is Min(I9) [max VC across TPS] or Min(I15) [fleet-wide weighted VC], changing cells are the “Rakes Diversion Program” column (F), subject to the source-wise and plant-wise bound constraints and the target-VC ceiling listed above. This Dashboard sheet is fully formula-linked to the solver sheet and refreshes automatically whenever Solver is re-run.

Sheet July 2026 (3)
A1: Coal Cost Dynamics ( tentative Variable cost due to coal)
A3: TPS | B3: Linkage/Bridge Linkage | C3: Name Of Coal Company | D3: Rakes alloted in July, 26 | E3: VC as per rake allocation in July 26 (Rs/Unit) | F3: RakesDiversion Program in July, 26 | G3: VC as per diverted rake in July 26 (Rs/Unit) | N3: Boundary Condition
A4: Harduaganj (110 MW) | B4: Linkage | C4: BCCL
C5: CCL
A7: Harduaganj (2X250 MW) | B7: Linkage | C7: BCCL | D7: 20 | E7: 4.78 | F7: 17.044527 | G7: 4.78 | N7: Individual Coal Source | O7: 0.4 | P7: 1.2
C8: CCL | D8: 40 | E8: 3.9 | F8: 48 | G8: 3.9 | N8: Plant Wise Coal Source | O8: 0.8 | P8: 1.1
D9: =SUM(D7:D8) -> 60 | E9: =IF( SUM(D7:D8)=0,0, SUMPRODUCT(E7:E8,D7:D8)/SUM(D7:D8)) -> 4.1933333 | F9: =SUM(F7:F8) -> 65.044527 | G9: =IF( SUM(F7:F8)=0,0, SUMPRODUCT(G7:G8,F7:F8)/SUM(F7:F8)) -> 4.1305987 | I9: =MAX(0,G9,G14,G18,G23,G29) -> 4.1305987 | N9: Total Rakes | O9: Cannot exceed scheduled Rakes Program | P9: =D30 -> 390
A10: Harduaganj (1X660 MW) | B10: Bridge Linkage | C10: CCL | D10: 30 | E10: 3.72 | F10: 36 | G10: 3.72 | N10: NCL | O10: =D31 -> 60
C11: SECL | D11: 20 | E11: 3.96 | F11: 20.925672 | G11: 3.96 | N11: BCCL | O11: =D32 -> 110
C12: NCL | D12: 0 | E12: 3.39 | F12: -1e-06 | G12: 3.39 | I12: =G9*F9+G14*F14+G18*F18+G23*F23+G29*F29 -> 1545.8652 | N12: CCL | O12: =D33 -> 155
C13: BCCL | D13: 15 | E13: 4.7 | F13: 14.57433 | G13: 4.7 | N13: SECL | O13: =D34 -> 65
D14: =SUM(D10:D13) -> 65 | E14: =IF(SUM(D10:D13)=0,0,SUMPRODUCT(E10:E13,D10:D13)/SUM(D10:D13)) -> 4.02 | F14: =SUM(F10:F13) -> 71.500001 | G14: =IF(SUM(F10:F13)=0,0,SUMPRODUCT(G10:G13,F10:F13)/SUM(F10:F13)) -> 3.9900001 | N14: ECL | O14: =D35 -> 0
A15: Parichha | B15: Linkage | C15: NCL | D15: 60 | E15: 3.93 | F15: 24.528302 | G15: 3.93 | I15: =I12/F30 -> 3.9637569 | N15: Weighatge Average VC | O15: =I15 -> 3.9637569
C16: CCL | D16: 25 | E16: 3.59 | F16: 30 | G16: 3.59 | N16: Maximum VC | O16: =MAX(0,E9,E14,E18,E23,E29) -> 4.43125
C17: BCCL | D17: 0 | E17: 4.99 | F17: 13.471698 | G17: 4.99 | N17: Target VC (<) | O17: 3.99
D18: =SUM(D15:D17) -> 85 | E18: =IF(SUM(D15:D17)=0,0,SUMPRODUCT(E15:E17,D15:D17)/SUM(D15:D17)) -> 3.83 | F18: =SUM(F15:F17) -> 68 | G18: =IF(SUM(F15:F17)=0,0,SUMPRODUCT(G15:G17,F15:F17)/SUM(F15:F17)) -> 3.99
A19: Panki | B19: Bridge Linkage | C19: CCL | D19: 60 | E19: 3.31 | F19: 41 | G19: 3.31
C20: BCCL | D20: 0 | E20: 4.33 | F20: 25 | G20: 4.33
C21: SECL | D21: 0 | E21: 3.5 | F21: 0 | G21: 3.5 | O21: =MIN($I$15) -> 3.9637569
C22: NCL | D22: 0 | E22: 2.8 | F22: 0 | G22: 2.8 | O22: =COUNT($F$7,$F$8,$F$10,$F$11,$F$12,$F$13,$F$15,$F$16,$F$17,$F$19,$F$20,$F$21,$F$22,$F$24,$F$25,$F$26,$F$27,$F$28) -> 18
D23: =SUM(D19:D22) -> 60 | E23: =IF(SUM(D19:D22)=0,0,SUMPRODUCT(E19:E22,D19:D22)/SUM(D19:D22)) -> 3.31 | F23: =SUM(F19:F22) -> 66 | G23: =IF(SUM(F19:F22)=0,0,SUMPRODUCT(G19:G22,F19:F22)/SUM(F19:F22)) -> 3.6963636 | O23: =$F$10<=$D$10*$P$7 -> TRUE
A24: Jawaharpur* | B24: Bridge Linkage | C24: CCL | D24: 0 | E24: 3.68 | F24: -7.1054274e-15 | G24: 3.68 | O24: =$F$10>=$D$10*$O$7 -> TRUE
C25: BCCL | D25: 75 | E25: 4.69 | F25: 39.909444 | G25: 4.69 | O25: =$F$11<=$D$11*$P$7 -> TRUE
C26: SECL | D26: 45 | E26: 4 | F26: 44.074328 | G26: 4 | O26: =$F$11>=$D$11*$O$7 -> TRUE
C27: NCL | D27: 0 | E27: 3.19 | F27: 35.471699 | G27: 3.19 | O27: =$F$13<=$D$13*$P$7 -> TRUE
C28: ECL | D28: 0 | E28: 4.78 | F28: 0 | G28: 4.78 | O28: =$F$13>=$D$13*$O$7 -> TRUE
D29: =SUM(D24:D28) -> 120 | E29: =IF(SUM(D24:D28)=0,0,SUMPRODUCT(E24:E28,D24:D28)/SUM(D24:D28)) -> 4.43125 | F29: =SUM(F24:F28) -> 119.45547 | G29: =IF(SUM(F24:F28)=0,0,SUMPRODUCT(G24:G28,F24:F28)/SUM(F24:F28)) -> 3.99 | O29: =$F$14<=$D$14*$P$8 -> FALSE
A30: Total UPRVUNL | B30: Linkage/Bridge Linkage | D30: =D9+D14+D18+D23+D29 -> 390 | F30: =F9+F14+F18+F23+F29 -> 390 | O30: =$F$14>=$D$14*$O$8 -> TRUE
C31: NCL | D31: =D15+D12+D22+D27 -> 60 | F31: =F15+F12+F22+F27 -> 60 | O31: =$F$15<=$D$15*$P$7 -> TRUE
C32: BCCL | D32: =D25+D20+D17+D13+D7 -> 110 | F32: =F25+F20+F17+F13+F7 -> 110 | O32: =$F$15>=$D$15*$O$7 -> TRUE
C33: CCL | D33: =D8+D10+D16+D19+D2431 -> 155 | F33: =F8+F10+F16+F19+F2431 -> 155 | O33: =$F$16<=$D$16*$P$7 -> TRUE
C34: SECL | D34: =D21+D26+D11 -> 65 | F34: =F21+F26+F11 -> 65 | O34: =$F$16>=$D$16*$O$7 -> TRUE
C35: ECL | D35: =D28 -> 0 | F35: =F28 -> 0 | O35: =$F$18<=$D$18*$P$8 -> TRUE
C36: TOTAL | D36: =SUM(D31:D35) -> 390 | F36: =SUM(F31:F35) -> 390 | O36: =$F$18>=$D$18*$O$8 -> TRUE
O37: =$F$19<=$D$19*$P$7 -> TRUE
O38: =$F$19>=$D$19*$O$7 -> TRUE
O39: =$F$23<=$D$23*$P$8 -> TRUE
O40: =$F$23>=$D$23*$O$8 -> TRUE
O41: =$F$25<=$D$25*$P$7 -> TRUE
O42: =$F$25>=$D$25*$O$7 -> TRUE
...

Sheet Calculation Sheet
A1: Coal Cost Dynamics ( tentative Variable cost due to coal)
A3: TPS | B3: Linkage/Bridge Linkage | C3: Name Of Coal Company | D3: Annual Coal Linkage (in Lac MT) | E3: Actual Coal Consumption in 2025-26 | F3: Rate of Coal (Rs/MT) | G3: Premium Rate (% of Basic Rate) | H3: Freight Rate (Rs/MT) | I3: Landed Cost of Coal (Rs/MT) | J3: Actual Landed cost of Coal in April 2026 | K3: Specific Coal Consumption (Kg/Kwh) | L3: APC | M3: Approx. Variable Charges (Rs/Unit) | N3: No. Of Rakes in a day as per MSQ | O3: Rakes allocated | P3: Expected Rate (Rs/Unit) | Q3: Rakes alloted in July, 26 | R3: VC as per rake allocation in July 26 (Rs/Unit) | S3: Rakes receipt planning in July 26 | T3: Probable VC after diversion of rakes in July 2026 (Rs/Unit) | U3: Current VC (Rs/Unit) for 01.07.26 to 15.07.26 | V3: Remarks
A4: Harduaganj (2X250 MW) | B4: Linkage | C4: BCCL | D4: 2.82 | E4: 9.59 | F4: 4497 | G4: 0 | H4: 2194 | I4: =F4+H4 -> 6691 | J4: 5297 | K4: 0.65 | L4: 9 | M4: =I4*K4/1000/(1-L4/100) -> 4.7792857 | N4: =D4/(365*3900)*100000 -> 0.19810327 | O4: 1 | Q4: 15 | S4: 20 | U4: 3.99
C5: CCL | D5: 21.69 | F5: 2349 | G5: 0 | H5: 2202 | I5: =F5+H5 -> 4551 | K5: 0.78 | L5: 9 | M5: =I5*K5/1000/(1-L5/100) -> 3.9008571 | N5: =D5/(365*3900)*100000 -> 1.5237092 | O5: 2 | Q5: 30 | S5: 30
D6: =SUM(D4:D5) -> 24.51 | F6: =(F4*D4+F5*D5)/D6 -> 2596.1383 | H6: =(H4*D4+H5*D5)/D6 -> 2201.0796 | I6: =F6+H6 -> 4797.2179 | K6: 0.765 | L6: 9 | M6: =I6*K6/1000/(1-L6/100) -> 4.032826 | N6: =D6/(365*3900)*100000 -> 1.7218124 | O6: 3 | P6: =(M4*O4+M5*O5)/O6 -> 4.1936667 | R6: =(M4*Q4+M5*Q5)/45 -> 4.1936667 | S6: =S4+S5 -> 50 | T6: =(S4*M4+S5*M5)/50 -> 4.2522286
A7: Harduaganj (1X660 MW) | B7: Bridge Linkage | C7: CCL | D7: 12.33 | E7: 19.25 | F7: 2700 | G7: 10 | H7: 2202 | I7: =F7+H7 -> 4902 | J7: 5382 | K7: 0.7 | L7: 7.65 | M7: =I7*K7/1000/(1-L7/100) -> 3.715647 | N7: =D7/(365*3900)*100000 -> 0.86617492 | O7: 1 | Q7: 30 | S7: 30 | U7: 3.81
C8: SECL | D8: 13.59 | F8: 3500 | G8: 10 | H8: =1990*1.05 -> 2089.5 | I8: =F8+H8 -> 5589.5 | K8: 0.654 | L8: 7.65 | M8: =I8*K8/1000/(1-L8/100) -> 3.9583465 | N8: =D8/(365*3900)*100000 -> 0.95468915 | O8: 1 | Q8: 15 | S8: 15
C9: NCL | F9: 3100 | G9: 0 | H9: =1606*1.05 -> 1686.3 | I9: =H9+F9 -> 4786.3 | K9: 0.654 | L9: 7.65 | M9: =I9*K9/1000/(1-L9/100) -> 3.38954 | N9: =D9/(365*3900)*100000 -> 0 | S9: 0
C10: BCCL | F10: 4800 | G10: 0 | H10: 2194 | I10: =F10+H10 -> 6994 | K10: 0.62 | L10: 7.65 | M10: =I10*K10/1000/(1-L10/100) -> 4.6954846 | N10: =D10/(365*3900)*100000 -> 0 | O10: 0.5 | Q10: 15 | S10: 10
D11: =SUM(D7:D10) -> 25.92 | F11: =(D7*F7+D8*F8)/(D7+D8) -> 3119.4444 | H11: =(D7*H7+D8*H8)/D11 -> 2143.0156 | I11: =F11+H11 -> 5262.4601 | K11: 0.675 | L11: 7.65 | M11: =I11*K11/1000/(1-L11/100) -> 3.846411 | N11: =D11/(365*3900)*100000 -> 1.8208641 | O11: 2.5 | P11: =(O7*M7+O8*M8+O10*M10)/O11 -> 4.0086943 | Q11: =SUM(Q7:Q10)+Q4+Q5 -> 105 | R11: =(M7*Q7+M8*Q8+M10*Q10)/60 -> 4.0212813 | S11: =S4+S5+S8+S9+S7 -> 95 | T11: =(M7*S7+M8*S8+M9*S9+M10*S10)/55 -> 3.9599901
A12: Parichha | B12: Linkage | C12: NCL | D12: 32.47 | E12: 33.76 | F12: 3100 | G12: 0 | H12: 1613 | I12: =F12+H12 -> 4713 | J12: 4701 | K12: 0.759 | L12: 9 | M12: =I12*K12/1000/(1-L12/100) -> 3.9309527 | N12: =D12/(365*3900)*100000 -> 2.2809975 | O12: 1.25 | Q12: 60 | S12: 50 | U12: 3.86
C13: CCL | D13: 8.08 | F13: 2349 | G13: 0 | H13: 1959 | I13: =F13+H13 -> 4308 | K13: 0.759 | L13: 9 | M13: =I13*K13/1000/(1-L13/100) -> 3.593156 | N13: =D13/(365*3900)*100000 -> 0.56761503 | O13: 0.5 | Q13: 21 | S13: 21
C14: BCCL | F14: 4500 | G14: 0 | H14: =1891*1.05 -> 1985.55 | I14: =H14+F14 -> 6485.55 | K14: 0.7 | L14: 9 | M14: =I14*K14/1000/(1-L14/100) -> 4.9888846 | N14: =D14/(365*3900)*100000 -> 0 | O14: 0.25 | S14: 10
D15: =SUM(D12:D13) -> 40.55 | F15: =(F12*D12+F13*D13)/D15 -> 2950.3556 | H15: =(H12*D12+H13*D13)/D15 -> 1681.944 | I15: =F15+H15 -> 4632.2996 | K15: 0.759 | L15: 9 | M15: =I15*K15/1000/(1-L15/100) -> 3.8636433 | N15: =D15/(365*3900)*100000 -> 2.8486126 | O15: =O12+O13+O14 -> 2 | P15: =(O12*M12+O13*M13+O14*M14)/O15 -> 3.9787451 | Q15: =SUM(Q12:Q14) -> 81 | R15: =(Q12*M12+Q13*M13)/Q15 -> 3.8433758 | S15: =SUM(S12:S14) -> 81 | T15: =(S12*M12+M13*S13+M14*S14)/S15 -> 3.9739847
A16: Panki | B16: Bridge Linkage | C16: CCL | D16: 24.66 | E16: 13.73 | F16: 2650 | G16: 10 | H16: 2007 | I16: =F16+H16 -> 4657 | J16: 4507 | K16: 0.67 | L16: 5.75 | M16: =I16*K16/1000/(1-L16/100) -> 3.3105464 | N16: =D16/(365*3900)*100000 -> 1.7323498 | O16: 1.5 | Q16: 53 | S16: 33 | U16: 3.31
C17: BCCL | F17: 4861 | G17: 10 | H17: 1665 | I17: =F17+H17 -> 6526 | K17: 0.625 | L17: 5.75 | M17: =I17*K17/1000/(1-L17/100) -> 4.3275862 | N17: =D17/(365*3900)*100000 -> 0 | O17: 0.5 | S17: 30
C18: SECL | F18: 3722 | G18: 10 | H18: =1484*1.05 -> 1558.2 | I18: =F18+H18 -> 5280.2 | K18: 0.625 | L18: 5.75 | M18: =I18*K18/1000/(1-L18/100) -> 3.5014589 | N18: =D18/(365*3900)*100000 -> 0 | S18: 0
C19: NCL | F19: 3100 | G19: 0 | H19: 1129 | I19: =F19+H19 -> 4229 | K19: 0.625 | L19: 5.75 | M19: =I19*K19/1000/(1-L19/100) -> 2.8043767 | N19: =D19/(365*3900)*100000 -> 0 | S19: 0
D20: =SUM(D16:D18) -> 24.66 | F20: =(D16*F16+D17*F17+D18*F18)/D20 -> 2650 | H20: =(D16*H16+D17*H17+D18*H18)/D20 -> 2007 | I20: =F20+H20 -> 4657 | K20: 0.625 | L20: 5.75 | M20: =I20*K20/1000/(1-L20/100) -> 3.0881963 | N20: =D20/(365*3900)*100000 -> 1.7323498 | O20: =SUM(O16:O19) -> 2 | P20: =(O16*M16+O17*M17)/2 -> 3.5648064 | Q20: =SUM(Q16:Q19) -> 53 | R20: =3.31 -> 3.31 | S20: =SUM(S16:S19) -> 63 | T20: =(M16*S16+M17*S17+M18*S18+M19*S19)/S20 -> 3.7948511
A21: Jawaharpur* | B21: Bridge Linkage | C21: CCL | D21: 0 | E21: 14.42 | F21: 3000 | G21: 10 | H21: 2342 | I21: =F21+H21 -> 5342 | J21: 6376 | K21: 0.65 | L21: 5.75 | M21: =I21*K21/1000/(1-L21/100) -> 3.6841379 | N21: 0 | P21: 0.5 | S21: 20 | U21: 4.09 | V21: Till 09.07.2026, Total rakes diverted = 11 rakes ( 9 rakes of BCCL from Jawaharpur to other plant 3-Hdj, 6-Panki). 2 CCL rakes of Panki diverted to jawaharpur TPS.
C22: BCCL | D22: 10.03 | F22: 4861 | G22: 10 | H22: 2215 | I22: =F22+H22 -> 7076 | K22: 0.625 | L22: 5.75 | M22: =I22*K22/1000/(1-L22/100) -> 4.6923077 | N22: =D22/(365*3900)*100000 -> 0.70460133 | P22: 1 | Q22: 60 | S22: 20
C23: SECL | D23: 27.17 | F23: 3722 | G23: 10 | H23: 2305 | I23: =F23+H23 -> 6027 | K23: 0.625 | L23: 5.75 | M23: =I23*K23/1000/(1-L23/100) -> 3.9966844 | N23: =D23/(365*3900)*100000 -> 1.9086758 | P23: 1 | Q23: 60 | S23: 60
C24: NCL | F24: 3100 | G24: 0 | H24: 1708 | I24: =F24+H24 -> 4808 | K24: 0.625 | L24: 5.75 | M24: =I24*K24/1000/(1-L24/100) -> 3.1883289 | N24: =D24/(365*3900)*100000 -> 0 | P24: 1 | S24: 10
C25: ECL | D25: 11.05 | F25: 5000 | G25: 0 | H25: 2215 | I25: =F25+H25 -> 7215 | K25: 0.625 | L25: 5.75 | M25: =I25*K25/1000/(1-L25/100) -> 4.7844828 | N25: =D25/(365*3900)*100000 -> 0.77625571
D26: =SUM(D21:D25) -> 48.25 | F26: =(F21*D21+F22*D22+F23*D23+F24*D24+F25*D25)/D26 -> 4251.4522 | H26: =(D21*H21+D22*H22+D23*H23+D24*H24+D25*H25)/D26 -> 2265.6798 | I26: =F26+H26 -> 6517.132 | K26: 0.625 | L26: 5.75 | M26: =I26*K26/1000/(1-L26/100) -> 4.3217056 | N26: =D26/(365*3900)*100000 -> 3.3895328 | P26: =SUM(P21:P25) -> 3.5 | Q26: =SUM(Q21:Q25) -> 120 | R26: =(Q22*M22+Q23*M23)/Q26 -> 4.344496 | S26: =SUM(S21:S25) -> 110 | T26: =(S21*M21+S22*M22+S23*M23+S24*M24)/S26 -> 3.9928478
A27: Total UPRVUNL | B27: Linkage/Bridge Linkage | Q27: =Q26+Q20+Q15+Q11 -> 359 | S27: =S6+S11+S15+S20+S26 -> 399
C28: NCL | N28: =N12 -> 2.2809975 | Q28: =Q12+Q9+Q19+Q24 -> 60 | S28: =S9+S12+S24+S19 -> 60
C29: BCCL | N29: =N22+N4 -> 0.9027046 | Q29: =Q22+Q17+Q14+Q10+Q4 -> 90 | S29: =S4+S10+S14+S17+S22 -> 90
C30: CCL | N30: =#REF!+N7+N13+N16+0.1 -> #REF! | Q30: =Q5+Q7+Q13+Q16+Q2427 -> 134 | S30: =S5+S13+S16+S21+S7 -> 134
C31: SECL | N31: =N23+N8 -> 2.8633649 | Q31: =Q18+Q23+Q8 -> 75 | S31: =S8+S18+S23 -> 75
C32: ECL | N32: =N25 -> 0.77625571 | Q32: =Q25 -> 0 | S32: =S25 -> 0
C33: TOTAL | N33: =N26+N20+N15+N11+N6 -> 11.513172 | Q33: =SUM(Q28:Q32) -> 359 | S33: =SUM(S28:S32) -> 359
